Workbook

Sheet COVER 1
B2: STANDARD TIME CALCULATION FORM
B4: YAMAHA ELECTRONICS MANUFACTURING INDONESIA (YEMI)
B6: MODEL | G6: : | R6: DOCUMENT NO | X6: :
R9: COVER PAGE | X9: : | Y9: 1 | Z9: of | AA9: 1
B10: SECTION | G10: : | R10: REVISION | X10: : | Y10: =MAX(F14:I51) -> 0 | AI10: --> REVISI Tertinggi otomatis terisi
B12: REVISION | F12: REVISION | J12: AMENDMENT | AC12: PREPARED
B13: DATE | F13: STATUS | AC13: BY
F14: 0 | J14: First Issue
B54: NOTE: | E54: THIS DOCUMENT IS YEMI CONFIDENTIAL PROPERTY. ANY UNAUTHORIZED
E55: DUPLICATION IN ANY FORM OR AS A WHOLE IS STRICTLY PROHIBITED.

Sheet Resume STCF
A1: SUMMARY STANDARD TIME CALCULATION FORM
A3: Part Number | C3: Part Name | F3: Qty/Product | G3: Total CT Average Man (min) | I3: Total CT Average Machine (min) | K3: Total CT (Man + Machine)
A4: VJM3960 | C4: TOP BOARD 73 | F4: 1
C5: COMPLETE ASSY J | F5: 1
C6: COMPLETE ASSY J | F6: 1
C7: COMPLETE ASSY U | F7: 1
C8: COMPLETE ASSY U | F8: 1

Sheet STCF 
A1: STANDARD TIME CALCULATION FORM | M1: Dokumen No. | O1: ='COVER 1'!Y6 -> 0
A2: Model | B2: : | C2: ='COVER 1'!H6 -> 0 | M2: MADE | O2: CHECKER | P2: APPROVER
A3: Section | B3: : | C3: ='COVER 1'!H10 -> 0 | O3: CHECKED & APPROVED BY WI/WF
A4: Rev No | B4: : | C4: ='COVER 1'!Y10 -> 0
A6: Part no | C6: Part name | D6: LOCATION CODE | E6: Nama Proses | H6: Step Proses | I6: Qty Material (pcs) | J6: Man/Machine | K6: Total Man | L6: Waktu Proses (sec) | O6: Cycle Time Average Man (min) | P6: Cycle Time Average Machine (min) | Q6: Kondisi STCF
L7: Cycle 1 | M7: Cycle 2 | N7: Cycle 3 | Q7: =IF(COUNTIF(Q8:Q11,"✅ OK")=COUNTA(Q8:Q11), "NORMAL", "ABNORMAL") -> ABNORMAL
D8: WW01 | E8: 1 | G8: =IF(E8="", G8, E8 & "." & 1) -> 1.1 | O8: =IFERROR(IF(J8="Man",AVERAGE(L8:N8))/I8/60,"") | P8: =IFERROR(IF(J8="Machine",AVERAGE(L8:N8))/I8/60,"") | Q8: =IF(MAX(L8:N8)/AVERAGE(L8:N8)>1.2, "⚠️ CYCLE "&MATCH(MAX(L8:N8),L8:N8,0)&" MENCOLOK", "✅ OK") -> #DIV/0!
D9: WW01 | G9: =IF(E8="", G8, E8 & "." & 2) -> 1.2 | O9: =IFERROR(IF(J9="Man",AVERAGE(L9:N9))/I9/60,"") | P9: =IFERROR(IF(J9="Machine",AVERAGE(L9:N9))/I9/60,"") | Q9: =IF(MAX(L9:N9)/AVERAGE(L9:N9)>1.3, "⚠️ CYCLE "&MATCH(MAX(L9:N9),L9:N9,0)&" MENCOLOK", "✅ OK") -> #DIV/0!
D10: WW01 | G10: =IF(E8="", G8, E8 & "." & 3) -> 1.3 | O10: =IFERROR(IF(J10="Man",AVERAGE(L10:N10))/I10/60,"") | P10: =IFERROR(IF(J10="Machine",AVERAGE(L10:N10))/I10/60,"") | Q10: =IF(MAX(L10:N10)/AVERAGE(L10:N10)>1.3, "⚠️ CYCLE "&MATCH(MAX(L10:N10),L10:N10,0)&" MENCOLOK", "✅ OK") -> #DIV/0!
D11: WW01 | G11: =IF(E8="", G8, E8 & "." & 4) -> 1.4 | O11: =IFERROR(IF(J11="Man",AVERAGE(L11:N11))/I11/60,"") | P11: =IFERROR(IF(J11="Machine",AVERAGE(L11:N11))/I11/60,"") | Q11: =IF(MAX(L11:N11)/AVERAGE(L11:N11)>1.3, "⚠️ CYCLE "&MATCH(MAX(L11:N11),L11:N11,0)&" MENCOLOK", "✅ OK") -> #DIV/0!
E12: 2 | G12: =IF(E12="", G12, E12 & "." & 1) -> 2.1 | O12: =IFERROR(IF(J12="Man",AVERAGE(L12:N12))/I12/60,"") | P12: =IFERROR(IF(J12="Machine",AVERAGE(L12:N12))/I12/60,"")
G13: =IF(E12="", G12, E12 & "." & 2) -> 2.2 | O13: =IFERROR(IF(J13="Man",AVERAGE(L13:N13))/I13/60,"") | P13: =IFERROR(IF(J13="Machine",AVERAGE(L13:N13))/I13/60,"")
G14: =IF(E12="", G12, E12 & "." & 3) -> 2.3 | O14: =IFERROR(IF(J14="Man",AVERAGE(L14:N14))/I14/60,"") | P14: =IFERROR(IF(J14="Machine",AVERAGE(L14:N14))/I14/60,"")
G15: =IF(E12="", G12, E12 & "." & 4) -> 2.4 | O15: =IFERROR(IF(J15="Man",AVERAGE(L15:N15))/I15/60,"") | P15: =IFERROR(IF(J15="Machine",AVERAGE(L15:N15))/I15/60,"")
E16: 3 | G16: =IF(E16="", G16, E16 & "." & 1) -> 3.1 | O16: =IFERROR(IF(J16="Man",AVERAGE(L16:N16))/I16/60,"") | P16: =IFERROR(IF(J16="Machine",AVERAGE(L16:N16))/I16/60,"")
G17: =IF(E16="", G16, E16 & "." & 2) -> 3.2 | O17: =IFERROR(IF(J17="Man",AVERAGE(L17:N17))/I17/60,"") | P17: =IFERROR(IF(J17="Machine",AVERAGE(L17:N17))/I17/60,"")
G18: =IF(E16="", G16, E16 & "." & 3) -> 3.3 | O18: =IFERROR(IF(J18="Man",AVERAGE(L18:N18))/I18/60,"") | P18: =IFERROR(IF(J18="Machine",AVERAGE(L18:N18))/I18/60,"")
G19: =IF(E16="", G16, E16 & "." & 4) -> 3.4 | O19: =IFERROR(IF(J19="Man",AVERAGE(L19:N19))/I19/60,"") | P19: =IFERROR(IF(J19="Machine",AVERAGE(L19:N19))/I19/60,"")
E20: 4 | G20: =IF(E20="", G20, E20 & "." & 1) -> 4.1 | O20: =IFERROR(IF(J20="Man",AVERAGE(L20:N20))/I20/60,"") | P20: =IFERROR(IF(J20="Machine",AVERAGE(L20:N20))/I20/60,"")
G21: =IF(E20="", G20, E20 & "." & 2) -> 4.2 | O21: =IFERROR(IF(J21="Man",AVERAGE(L21:N21))/I21/60,"") | P21: =IFERROR(IF(J21="Machine",AVERAGE(L21:N21))/I21/60,"")
G22: =IF(E20="", G20, E20 & "." & 3) -> 4.3 | O22: =IFERROR(IF(J22="Man",AVERAGE(L22:N22))/I22/60,"") | P22: =IFERROR(IF(J22="Machine",AVERAGE(L22:N22))/I22/60,"")
G23: =IF(E20="", G20, E20 & "." & 4) -> 4.4 | O23: =IFERROR(IF(J23="Man",AVERAGE(L23:N23))/I23/60,"") | P23: =IFERROR(IF(J23="Machine",AVERAGE(L23:N23))/I23/60,"")
E24: 5 | G24: =IF(E24="", G24, E24 & "." & 1) -> 5.1 | O24: =IFERROR(IF(J24="Man",AVERAGE(L24:N24))/I24/60,"") | P24: =IFERROR(IF(J24="Machine",AVERAGE(L24:N24))/I24/60,"")
G25: =IF(E24="", G24, E24 & "." & 2) -> 5.2 | O25: =IFERROR(IF(J25="Man",AVERAGE(L25:N25))/I25/60,"") | P25: =IFERROR(IF(J25="Machine",AVERAGE(L25:N25))/I25/60,"")
G26: =IF(E24="", G24, E24 & "." & 3) -> 5.3 | O26: =IFERROR(IF(J26="Man",AVERAGE(L26:N26))/I26/60,"") | P26: =IFERROR(IF(J26="Machine",AVERAGE(L26:N26))/I26/60,"")
G27: =IF(E24="", G24, E24 & "." & 4) -> 5.4 | O27: =IFERROR(IF(J27="Man",AVERAGE(L27:N27))/I27/60,"") | P27: =IFERROR(IF(J27="Machine",AVERAGE(L27:N27))/I27/60,"")
E28: 6 | G28: =IF(E28="", G28, E28 & "." & 1) -> 6.1 | O28: =IFERROR(IF(J28="Man",AVERAGE(L28:N28))/I28/60,"") | P28: =IFERROR(IF(J28="Machine",AVERAGE(L28:N28))/I28/60,"")
G29: =IF(E28="", G28, E28 & "." & 2) -> 6.2 | O29: =IFERROR(IF(J29="Man",AVERAGE(L29:N29))/I29/60,"") | P29: =IFERROR(IF(J29="Machine",AVERAGE(L29:N29))/I29/60,"")
G30: =IF(E28="", G28, E28 & "." & 3) -> 6.3 | O30: =IFERROR(IF(J30="Man",AVERAGE(L30:N30))/I30/60,"") | P30: =IFERROR(IF(J30="Machine",AVERAGE(L30:N30))/I30/60,"")
G31: =IF(E28="", G28, E28 & "." & 4) -> 6.4 | O31: =IFERROR(IF(J31="Man",AVERAGE(L31:N31))/I31/60,"") | P31: =IFERROR(IF(J31="Machine",AVERAGE(L31:N31))/I31/60,"")
E32: 7 | G32: =IF(E32="", G32, E32 & "." & 1) -> 7.1 | O32: =IFERROR(IF(J32="Man",AVERAGE(L32:N32))/I32/60,"") | P32: =IFERROR(IF(J32="Machine",AVERAGE(L32:N32))/I32/60,"")
G33: =IF(E32="", G32, E32 & "." & 2) -> 7.2 | O33: =IFERROR(IF(J33="Man",AVERAGE(L33:N33))/I33/60,"") | P33: =IFERROR(IF(J33="Machine",AVERAGE(L33:N33))/I33/60,"")
G34: =IF(E32="", G32, E32 & "." & 3) -> 7.3 | O34: =IFERROR(IF(J34="Man",AVERAGE(L34:N34))/I34/60,"") | P34: =IFERROR(IF(J34="Machine",AVERAGE(L34:N34))/I34/60,"")
G35: =IF(E32="", G32, E32 & "." & 4) -> 7.4 | O35: =IFERROR(IF(J35="Man",AVERAGE(L35:N35))/I35/60,"") | P35: =IFERROR(IF(J35="Machine",AVERAGE(L35:N35))/I35/60,"")
E36: 8 | G36: =IF(E36="", G36, E36 & "." & 1) -> 8.1 | O36: =IFERROR(IF(J36="Man",AVERAGE(L36:N36))/I36/60,"") | P36: =IFERROR(IF(J36="Machine",AVERAGE(L36:N36))/I36/60,"")
G37: =IF(E36="", G36, E36 & "." & 2) -> 8.2 | O37: =IFERROR(IF(J37="Man",AVERAGE(L37:N37))/I37/60,"") | P37: =IFERROR(IF(J37="Machine",AVERAGE(L37:N37))/I37/60,"")
G38: =IF(E36="", G36, E36 & "." & 3) -> 8.3 | O38: =IFERROR(IF(J38="Man",AVERAGE(L38:N38))/I38/60,"") | P38: =IFERROR(IF(J38="Machine",AVERAGE(L38:N38))/I38/60,"")
G39: =IF(E36="", G36, E36 & "." & 4) -> 8.4 | O39: =IFERROR(IF(J39="Man",AVERAGE(L39:N39))/I39/60,"") | P39: =IFERROR(IF(J39="Machine",AVERAGE(L39:N39))/I39/60,"")
E40: 9 | G40: =IF(E40="", G40, E40 & "." & 1) -> 9.1 | O40: =IFERROR(IF(J40="Man",AVERAGE(L40:N40))/I40/60,"") | P40: =IFERROR(IF(J40="Machine",AVERAGE(L40:N40))/I40/60,"")
G41: =IF(E40="", G40, E40 & "." & 2) -> 9.2 | O41: =IFERROR(IF(J41="Man",AVERAGE(L41:N41))/I41/60,"") | P41: =IFERROR(IF(J41="Machine",AVERAGE(L41:N41))/I41/60,"")
...

Sheet STCF MP
A1: STANDARD TIME CALCULATION FORM (MASS PRODUCTION) | M1: Dokumen No. | O1: ='COVER 1'!Y6 -> 0
A2: Model : | B2: ='COVER 1'!H6 -> 0 | M2: MADE | O2: CHECKER | P2: APPROVER
A3: Section : | B3: ='COVER 1'!H10 -> 0 | O3: CHECKED & APPROVED BY WI/WF
A4: Rev No : | B4: ='COVER 1'!Y10 -> 0
A6: Part no | B6: Part name | C6: LOCATION CODE | D6: Nama Proses | G6: Step Proses | H6: Manual/Machine | I6: Qty Material (pcs) | J6: Man/Machine | K6: Total Man | L6: Waktu Proses (sec) | O6: Cycle Time Average Man (min) | P6: Cycle Time Average Machine (min)
L7: Cycle 1 | M7: Cycle 2 | N7: Cycle 3
A8: VJM3960 | B8: TOP BOARD 73 | C8: WW01 | D8: 1 | E8: Proses Pemotongan Top Board | F8: 1.1 | G8: Ambil Raw Material dan letakan pada mesin | H8: Manual | I8: 3 | J8: =IF(H8="", "", IF(LOWER(H8)="Manual", "Man", "Machine")) -> Man | K8: 1 | L8: 9 | M8: 8.8 | N8: 8.6 | O8: =IFERROR(IF(J8="Man",AVERAGE(L8:N8)*K8)/I8,0) -> 2.9333333 | P8: =IFERROR(IF(J8="Machine",(AVERAGE(L8:N8)/I8)/60,0),0) -> 0
A9: VJM3960 | B9: TOP BOARD 73 | C9: WW01 | F9: 1.2 | G9: Proses Pemotongan | H9: Running Saw | I9: 3 | J9: =IF(H9="", "", IF(LOWER(H9)="Manual", "Man", "Machine")) -> Machine | K9: 0 | L9: 5 | M9: 5.2 | N9: 5.4 | O9: =IFERROR(IF(J9="Man",AVERAGE(L9:N9)*K9)/I9,0) -> 0 | P9: =IFERROR(IF(J9="Machine",(AVERAGE(L9:N9)/I9)/60,0),0) -> 0.028888889
A10: VJM3960 | B10: TOP BOARD 73 | C10: WW01 | F10: 1.3 | G10: Pengecekan Hasil Proses | H10: Manual | I10: 1 | J10: =IF(H10="", "", IF(LOWER(H10)="Manual", "Man", "Machine")) -> Man | K10: 1 | L10: 1.9 | M10: 1.87 | N10: 2 | O10: =IFERROR(IF(J10="Man",AVERAGE(L10:N10)*K10)/I10,0) -> 1.9233333 | P10: =IFERROR(IF(J10="Machine",(AVERAGE(L10:N10)/I10)/60,0),0) -> 0
A11: VJM3960 | B11: TOP BOARD 73 | C11: WW01 | F11: 1.4 | G11: Letakan hasil potong pada pallet | H11: Manual | I11: 6 | J11: =IF(H11="", "", IF(LOWER(H11)="Manual", "Man", "Machine")) -> Man | K11: 1 | L11: 1.75 | M11: 1.55 | N11: 2 | O11: =IFERROR(IF(J11="Man",AVERAGE(L11:N11)*K11)/I11,0) -> 0.29444444 | P11: =IFERROR(IF(J11="Machine",(AVERAGE(L11:N11)/I11)/60,0),0) -> 0
D12: 2 | F12: 2.1 | J12: =IF(H12="", "", IF(LOWER(H12)="Manual", "Man", "Machine")) | O12: =IFERROR(IF(J12="Man",AVERAGE(L12:N12)*K12)/I12,0) -> 0 | P12: =IFERROR(IF(J12="Machine",(AVERAGE(L12:N12)/I12)/60,0),0) -> 0
F13: 2.2 | J13: =IF(H13="", "", IF(LOWER(H13)="Manual", "Man", "Machine")) | O13: =IFERROR(IF(J13="Man",AVERAGE(L13:N13)*K13)/I13,0) -> 0 | P13: =IFERROR(IF(J13="Machine",(AVERAGE(L13:N13)/I13)/60,0),0) -> 0
F14: 2.3 | J14: =IF(H14="", "", IF(LOWER(H14)="Manual", "Man", "Machine")) | O14: =IFERROR(IF(J14="Man",AVERAGE(L14:N14)*K14)/I14,0) -> 0 | P14: =IFERROR(IF(J14="Machine",(AVERAGE(L14:N14)/I14)/60,0),0) -> 0
F15: 2.4 | J15: =IF(H15="", "", IF(LOWER(H15)="Manual", "Man", "Machine")) | O15: =IFERROR(IF(J15="Man",AVERAGE(L15:N15)*K15)/I15,0) -> 0 | P15: =IFERROR(IF(J15="Machine",(AVERAGE(L15:N15)/I15)/60,0),0) -> 0
D16: 3 | F16: 3.1 | J16: =IF(H16="", "", IF(LOWER(H16)="Manual", "Man", "Machine")) | O16: =IFERROR(IF(J16="Man",AVERAGE(L16:N16)*K16)/I16,0) -> 0 | P16: =IFERROR(IF(J16="Machine",(AVERAGE(L16:N16)/I16)/60,0),0) -> 0
F17: 3.2 | J17: =IF(H17="", "", IF(LOWER(H17)="Manual", "Man", "Machine")) | O17: =IFERROR(IF(J17="Man",AVERAGE(L17:N17)*K17)/I17,0) -> 0 | P17: =IFERROR(IF(J17="Machine",(AVERAGE(L17:N17)/I17)/60,0),0) -> 0
F18: 3.3 | J18: =IF(H18="", "", IF(LOWER(H18)="Manual", "Man", "Machine")) | O18: =IFERROR(IF(J18="Man",AVERAGE(L18:N18)*K18)/I18,0) -> 0 | P18: =IFERROR(IF(J18="Machine",(AVERAGE(L18:N18)/I18)/60,0),0) -> 0
F19: 3.4 | J19: =IF(H19="", "", IF(LOWER(H19)="Manual", "Man", "Machine")) | O19: =IFERROR(IF(J19="Man",AVERAGE(L19:N19)*K19)/I19,0) -> 0 | P19: =IFERROR(IF(J19="Machine",(AVERAGE(L19:N19)/I19)/60,0),0) -> 0
D20: 4 | F20: 4.1 | J20: =IF(H20="", "", IF(LOWER(H20)="Manual", "Man", "Machine")) | O20: =IFERROR(IF(J20="Man",AVERAGE(L20:N20)*K20)/I20,0) -> 0 | P20: =IFERROR(IF(J20="Machine",(AVERAGE(L20:N20)/I20)/60,0),0) -> 0
F21: 4.2 | J21: =IF(H21="", "", IF(LOWER(H21)="Manual", "Man", "Machine")) | O21: =IFERROR(IF(J21="Man",AVERAGE(L21:N21)*K21)/I21,0) -> 0 | P21: =IFERROR(IF(J21="Machine",(AVERAGE(L21:N21)/I21)/60,0),0) -> 0
F22: 4.3 | J22: =IF(H22="", "", IF(LOWER(H22)="Manual", "Man", "Machine")) | O22: =IFERROR(IF(J22="Man",AVERAGE(L22:N22)*K22)/I22,0) -> 0 | P22: =IFERROR(IF(J22="Machine",(AVERAGE(L22:N22)/I22)/60,0),0) -> 0
F23: 4.4 | J23: =IF(H23="", "", IF(LOWER(H23)="Manual", "Man", "Machine")) | O23: =IFERROR(IF(J23="Man",AVERAGE(L23:N23)*K23)/I23,0) -> 0 | P23: =IFERROR(IF(J23="Machine",(AVERAGE(L23:N23)/I23)/60,0),0) -> 0
D24: 5 | F24: 5.1 | J24: =IF(H24="", "", IF(LOWER(H24)="Manual", "Man", "Machine")) | O24: =IFERROR(IF(J24="Man",AVERAGE(L24:N24)*K24)/I24,0) -> 0 | P24: =IFERROR(IF(J24="Machine",(AVERAGE(L24:N24)/I24)/60,0),0) -> 0
F25: 5.2 | J25: =IF(H25="", "", IF(LOWER(H25)="Manual", "Man", "Machine")) | O25: =IFERROR(IF(J25="Man",AVERAGE(L25:N25)*K25)/I25,0) -> 0 | P25: =IFERROR(IF(J25="Machine",(AVERAGE(L25:N25)/I25)/60,0),0) -> 0
F26: 5.3 | J26: =IF(H26="", "", IF(LOWER(H26)="Manual", "Man", "Machine")) | O26: =IFERROR(IF(J26="Man",AVERAGE(L26:N26)*K26)/I26,0) -> 0 | P26: =IFERROR(IF(J26="Machine",(AVERAGE(L26:N26)/I26)/60,0),0) -> 0
F27: 5.4 | J27: =IF(H27="", "", IF(LOWER(H27)="Manual", "Man", "Machine")) | O27: =IFERROR(IF(J27="Man",AVERAGE(L27:N27)*K27)/I27,0) -> 0 | P27: =IFERROR(IF(J27="Machine",(AVERAGE(L27:N27)/I27)/60,0),0) -> 0
D28: 6 | F28: 6.1 | J28: =IF(H28="", "", IF(LOWER(H28)="Manual", "Man", "Machine")) | O28: =IFERROR(IF(J28="Man",AVERAGE(L28:N28)*K28)/I28,0) -> 0 | P28: =IFERROR(IF(J28="Machine",(AVERAGE(L28:N28)/I28)/60,0),0) -> 0
F29: 6.2 | J29: =IF(H29="", "", IF(LOWER(H29)="Manual", "Man", "Machine")) | O29: =IFERROR(IF(J29="Man",AVERAGE(L29:N29)*K29)/I29,0) -> 0 | P29: =IFERROR(IF(J29="Machine",(AVERAGE(L29:N29)/I29)/60,0),0) -> 0
F30: 6.3 | J30: =IF(H30="", "", IF(LOWER(H30)="Manual", "Man", "Machine")) | O30: =IFERROR(IF(J30="Man",AVERAGE(L30:N30)*K30)/I30,0) -> 0 | P30: =IFERROR(IF(J30="Machine",(AVERAGE(L30:N30)/I30)/60,0),0) -> 0
F31: 6.4 | J31: =IF(H31="", "", IF(LOWER(H31)="Manual", "Man", "Machine")) | O31: =IFERROR(IF(J31="Man",AVERAGE(L31:N31)*K31)/I31,0) -> 0 | P31: =IFERROR(IF(J31="Machine",(AVERAGE(L31:N31)/I31)/60,0),0) -> 0
D32: 7 | F32: 7.1 | J32: =IF(H32="", "", IF(LOWER(H32)="Manual", "Man", "Machine")) | O32: =IFERROR(IF(J32="Man",AVERAGE(L32:N32)*K32)/I32,0) -> 0 | P32: =IFERROR(IF(J32="Machine",(AVERAGE(L32:N32)/I32)/60,0),0) -> 0
F33: 7.2 | J33: =IF(H33="", "", IF(LOWER(H33)="Manual", "Man", "Machine")) | O33: =IFERROR(IF(J33="Man",AVERAGE(L33:N33)*K33)/I33,0) -> 0 | P33: =IFERROR(IF(J33="Machine",(AVERAGE(L33:N33)/I33)/60,0),0) -> 0
F34: 7.3 | J34: =IF(H34="", "", IF(LOWER(H34)="Manual", "Man", "Machine")) | O34: =IFERROR(IF(J34="Man",AVERAGE(L34:N34)*K34)/I34,0) -> 0 | P34: =IFERROR(IF(J34="Machine",(AVERAGE(L34:N34)/I34)/60,0),0) -> 0
F35: 7.4 | J35: =IF(H35="", "", IF(LOWER(H35)="Manual", "Man", "Machine")) | O35: =IFERROR(IF(J35="Man",AVERAGE(L35:N35)*K35)/I35,0) -> 0 | P35: =IFERROR(IF(J35="Machine",(AVERAGE(L35:N35)/I35)/60,0),0) -> 0
D36: 8 | F36: 8.1 | J36: =IF(H36="", "", IF(LOWER(H36)="Manual", "Man", "Machine")) | O36: =IFERROR(IF(J36="Man",AVERAGE(L36:N36)*K36)/I36,0) -> 0 | P36: =IFERROR(IF(J36="Machine",(AVERAGE(L36:N36)/I36)/60,0),0) -> 0
F37: 8.2 | J37: =IF(H37="", "", IF(LOWER(H37)="Manual", "Man", "Machine")) | O37: =IFERROR(IF(J37="Man",AVERAGE(L37:N37)*K37)/I37,0) -> 0 | P37: =IFERROR(IF(J37="Machine",(AVERAGE(L37:N37)/I37)/60,0),0) -> 0
F38: 8.3 | J38: =IF(H38="", "", IF(LOWER(H38)="Manual", "Man", "Machine")) | O38: =IFERROR(IF(J38="Man",AVERAGE(L38:N38)*K38)/I38,0) -> 0 | P38: =IFERROR(IF(J38="Machine",(AVERAGE(L38:N38)/I38)/60,0),0) -> 0
F39: 8.4 | J39: =IF(H39="", "", IF(LOWER(H39)="Manual", "Man", "Machine")) | O39: =IFERROR(IF(J39="Man",AVERAGE(L39:N39)*K39)/I39,0) -> 0 | P39: =IFERROR(IF(J39="Machine",(AVERAGE(L39:N39)/I39)/60,0),0) -> 0
D40: 9 | F40: 9.1 | J40: =IF(H40="", "", IF(LOWER(H40)="Manual", "Man", "Machine")) | O40: =IFERROR(IF(J40="Man",AVERAGE(L40:N40)*K40)/I40,0) -> 0 | P40: =IFERROR(IF(J40="Machine",(AVERAGE(L40:N40)/I40)/60,0),0) -> 0
F41: 9.2 | J41: =IF(H41="", "", IF(LOWER(H41)="Manual", "Man", "Machine")) | O41: =IFERROR(IF(J41="Man",AVERAGE(L41:N41)*K41)/I41,0) -> 0 | P41: =IFERROR(IF(J41="Machine",(AVERAGE(L41:N41)/I41)/60,0),0) -> 0
...

Sheet Data mesin Mtnc
F1: Document | G1: Document | H1: Document | I1: Category | J1: Location | K1: Area | L1: Machine Rating | M1: Incoming Date | N1: Machine Life | O1: Country Of Origin | P1: Iot Category
A2: Asset ID | B2: QR Code | C2: Category PE | D2: Description | E2: Kode mesin | F2: (Electrical) | G2: (Manual Book) | H2: (Sparepart)
A3: MNT00001 | B3: MNT00001 | C3: Band(o) Saw | D3: BAND SAW (SOCOMECC) | E3: =B3 -> MNT00001 | F3: - | H3: - | I3: KONVENSIONAL | J3: FACTORY 1 | K3: WOOD WORKING | L3: B | M3: 37833 | N3: 19 | O3: Italy | P3: Non IoT
A4: MNT00004 | B4: MNT00004 | C4: Pin router Jepang | D4: PIN ROUTER NO.3 (SHODA RO 116) | E4: =B4 -> MNT00004 | F4: - | H4: - | I4: KONVENSIONAL | J4: FACTORY 1 | K4: WOOD WORKING | L4: B | M4: 36922 | N4: 21 | O4: Japan | P4: Non IoT
A5: MNT00005 | B5: MNT00005 | C5: Pin router Jepang | D5: PIN ROUTER NO.4 (SHODA RO 116) | E5: =B5 -> MNT00005 | F5: - | H5: - | I5: KONVENSIONAL | J5: FACTORY 1 | K5: WOOD WORKING | L5: B | M5: 36922 | N5: 21 | O5: Japan | P5: Non IoT
A6: MNT00006 | B6: MNT00006 | C6: Pin router Jepang | D6: PIN ROUTER NO.5 (SHODA RO 116) | E6: =B6 -> MNT00006 | F6: - | H6: - | I6: KONVENSIONAL | J6: FACTORY 1 | K6: WOOD WORKING | L6: B | M6: 36922 | N6: 21 | O6: Japan | P6: Non IoT
A7: MNT00007 | B7: MNT00007 | C7: Pin router Jepang | D7: PIN ROUTER NO.6 (SHODA RO 116) | E7: =B7 -> MNT00007 | F7: - | H7: - | I7: KONVENSIONAL | J7: FACTORY 1 | K7: WOOD WORKING | L7: B | M7: 36922 | N7: 21 | O7: Japan | P7: Non IoT
A8: MNT00008 | B8: MNT00008 | C8: Pin router Jepang | D8: PIN ROUTER NO.7 (SHODA RO 116) | E8: =B8 -> MNT00008 | F8: - | H8: - | I8: KONVENSIONAL | J8: FACTORY 1 | K8: WOOD WORKING | L8: B | M8: 36922 | N8: 21 | O8: Japan | P8: Non IoT
A9: MNT00012 | B9: MNT00012 | C9: Pinr Router China | D9: PIN ROUTER NO.11 (HOLYTEK HR-7) | E9: =B9 -> MNT00012 | F9: - | H9: - | I9: KONVENSIONAL | J9: FACTORY 1 | K9: WOOD WORKING | L9: B | M9: 41608 | N9: 9 | O9: Taiwan | P9: Non IoT
A10: MNT00013 | B10: MNT00013 | C10: Pinr Router China | D10: PIN ROUTER NO.12 (HOLYTEK HR-7) | E10: =B10 -> MNT00013 | F10: - | H10: - | I10: KONVENSIONAL | J10: FACTORY 1 | K10: WOOD WORKING | L10: B | M10: 41608 | N10: 9 | O10: Taiwan | P10: Non IoT
A11: MNT00014 | B11: MNT00014 | C11: Pinr Router China | D11: PIN ROUTER NO.13 (HOLYTEK HR-7) | E11: =B11 -> MNT00014 | F11: - | H11: - | I11: KONVENSIONAL | J11: FACTORY 1 | K11: WOOD WORKING | L11: B | M11: 41608 | N11: 9 | O11: Taiwan | P11: Non IoT
A12: MNT00015 | B12: MNT00015 | C12: Pinr Router China | D12: PIN ROUTER NO.14 (HOLYTEK HR-7) | E12: =B12 -> MNT00015 | F12: - | H12: - | I12: KONVENSIONAL | J12: FACTORY 1 | K12: WOOD WORKING | L12: B | M12: 41608 | N12: 9 | O12: Taiwan | P12: Non IoT
A13: MNT00016 | B13: MNT00016 | C13: Panel Saw | D13: PANEL SAW NO.1 (ISHIZU) | E13: =B13 -> MNT00016 | F13: - | H13: - | I13: KONVENSIONAL | J13: FACTORY 1 | K13: WOOD WORKING | L13: B | M13: 36433 | N13: 23 | O13: Japan | P13: Non IoT
A14: MNT00017 | B14: MNT00017 | C14: Panel Saw | D14: PANEL SAW NO.2 (SHINX) | E14: =B14 -> MNT00017 | H14: - | I14: KONVENSIONAL | J14: FACTORY 1 | K14: WOOD WORKING | L14: B | M14: 42490 | N14: 6 | O14: Japan | P14: IoT
A15: MNT00018 | B15: MNT00018 | C15: WBS - Wide Belt Sander | D15: WIDE BELT SANDER (AMITEC) | E15: =B15 -> MNT00018 | F15: - | H15: - | I15: KONVENSIONAL | J15: FACTORY 1 | K15: WOOD WORKING | L15: S | M15: 36433 | N15: 23 | O15: Japan | P15: Non IoT
A16: MNT00019 | B16: MNT00019 | C16: Flat laminator | D16: FLAT LAMINATOR (SUGII MACHINEERY WORKS) | E16: =B16 -> MNT00019 | H16: - | I16: KONVENSIONAL | J16: FACTORY 1 | K16: WOOD WORKING | L16: S | M16: 36433 | N16: 23 | O16: Japan | P16: Non IoT
A17: MNT00020 | B17: MNT00020 | C17: Hot press 700 series | D17: HOT PRESS 700 series (TIRTAMAS PERKASA) | E17: =B17 -> MNT00020 | F17: - | G17: - | H17: - | I17: KONVENSIONAL | J17: FACTORY 1 | K17: WOOD WORKING | L17: A | M17: 39660 | N17: 14 | O17: Indonesia | P17: Non IoT
A18: MNT00021 | B18: MNT00021 | C18: Running Saw | D18: RUNNING SAW 1 (HOLZMA) | E18: =B18 -> MNT00021 | I18: KONVENSIONAL | J18: FACTORY 1 | K18: WOOD WORKING | L18: S | M18: 40178 | N18: 13 | O18: Germany | P18: IoT
A19: MNT00022 | B19: MNT00022 | C19: Running Saw | D19: RUNNING SAW 2 (HOLZMA) | E19: =B19 -> MNT00022 | I19: KONVENSIONAL | J19: FACTORY 1 | K19: WOOD WORKING | L19: S | M19: 40786 | N19: 11 | O19: Germany | P19: IoT
A20: MNT00023 | B20: MNT00023 | C20: Running Saw | D20: RUNNING SAW 3 (SCM) | E20: =B20 -> MNT00023 | I20: KONVENSIONAL | J20: FACTORY 1 | K20: WOOD WORKING | L20: S | M20: 42094 | N20: 7 | O20: Italy | P20: IoT
A21: MNT00024 | B21: MNT00024 | C21: Moulder | D21: MOULDER NO. 11 LINE BR (RULONG) | E21: =B21 -> MNT00024 | F21: - | H21: - | I21: KONVENSIONAL | J21: FACTORY 1 | K21: WOOD WORKING | L21: B | M21: 41578 | N21: 9 | O21: Taiwan | P21: Non IoT
A22: MNT00025 | B22: MNT00025 | C22: Moulder | D22: MOULDER NO. 12 LINE BR (RULONG) | E22: =B22 -> MNT00025 | F22: - | H22: - | I22: KONVENSIONAL | J22: FACTORY 1 | K22: WOOD WORKING | L22: B | M22: 41578 | N22: 9 | O22: Taiwan | P22: Non IoT
A23: MNT00026 | B23: MNT00026 | C23: Moulder | D23: MOULDER NO. 1 CABINET (CHAMFOND) | E23: =B23 -> MNT00026 | F23: - | H23: - | I23: KONVENSIONAL | J23: FACTORY 1 | K23: WOOD WORKING | L23: B | M23: 38503 | N23: 17 | O23: Taiwan | P23: Non IoT
A24: MNT00027 | B24: MNT00027 | C24: VVC line moulder | D24: MOULDER NO. 4 VVC 1 (CHAMFOND) | E24: =B24 -> MNT00027 | F24: - | H24: - | I24: KONVENSIONAL | J24: FACTORY 1 | K24: WOOD WORKING | L24: B | M24: 37894 | N24: 19 | O24: Taiwan | P24: Non IoT
A25: MNT00028 | B25: MNT00028 | C25: VVC line moulder | D25: MOULDER NO. 5 VVC 1 (CHAMFOND) | E25: =B25 -> MNT00028 | F25: - | H25: - | I25: KONVENSIONAL | J25: FACTORY 1 | K25: WOOD WORKING | L25: B | M25: 37590 | N25: 20 | O25: Taiwan | P25: Non IoT
A26: MNT00029 | B26: MNT00029 | C26: Hozo line moulder | D26: MOULDER NO. 10 HOZOLINE (SHODA) | E26: =B26 -> MNT00029 | F26: - | H26: - | I26: KONVENSIONAL | J26: FACTORY 1 | K26: WOOD WORKING | L26: B | M26: 37560 | N26: 20 | O26: Japan | P26: Non IoT
A27: MNT00030 | B27: MNT00030 | C27: Hozo line moulder | D27: MOULDER NO. 9 HOZOLINE (SHODA) | E27: =B27 -> MNT00030 | F27: - | H27: - | I27: KONVENSIONAL | J27: FACTORY 1 | K27: WOOD WORKING | L27: B | M27: 37407 | N27: 20 | O27: Japan | P27: Non IoT
A28: MNT00032 | B28: MNT00032 | C28: Moulder | D28: MOULDER NO. 7 NCR4 AREA (RULONG) | E28: =B28 -> MNT00032 | F28: - | H28: - | I28: KONVENSIONAL | J28: FACTORY 1 | K28: WOOD WORKING | L28: B | M28: 41578 | N28: 9 | O28: Taiwan | P28: Non IoT
A29: MNT00033 | B29: MNT00033 | C29: Moulder | D29: MOULDER NO. 2 CABINET (CHAMFOND) | E29: =B29 -> MNT00033 | F29: - | H29: - | I29: KONVENSIONAL | J29: FACTORY 1 | K29: WOOD WORKING | L29: B | M29: 36707 | N29: 22 | O29: Taiwan | P29: Non IoT
A30: MNT00034 | B30: MNT00034 | C30: Moulder | D30: MOULDER NO. 3 CABINET (CHAMFOND) | E30: =B30 -> MNT00034 | F30: - | H30: - | I30: KONVENSIONAL | J30: FACTORY 1 | K30: WOOD WORKING | L30: B | M30: 36707 | N30: 22 | O30: Taiwan | P30: Non IoT
A31: MNT00038 | B31: MNT00038 | C31: Mizo line Bench Saw | D31: BENCH SAW NO. 6 MIZOLINE (TOKAI) | E31: =B31 -> MNT00038 | F31: - | H31: - | I31: KONVENSIONAL | J31: FACTORY 1 | K31: WOOD WORKING | L31: B | M31: 37407 | N31: 20 | O31: Japan | P31: Non IoT
A32: MNT00039 | B32: MNT00039 | C32: Mizo line Bench Saw | D32: BENCH SAW NO. 14 MIZOLINE (TOKAI) | E32: =B32 -> MNT00039 | F32: - | H32: - | I32: KONVENSIONAL | J32: FACTORY 1 | K32: WOOD WORKING | L32: B | M32: 37407 | N32: 20 | O32: Japan | P32: Non IoT
... A41: MNT00048 | B41: MNT00048 | C41: Bench Saw Body Line | D41: BENCH SAW NO. 3 BODY LINE (AUTOFEEDER) | E41: =B41 -> MNT00048 | F41: - | H41: - | I41: KONVENSIONAL | J41: FACTORY 1 | K41: WOOD WORKING | L41: B | M41: 37407 | N41: 20 | O41: Japan | P41: Non IoT
A42: MNT00052 | B42: MNT00052 | C42: NC Router ( Heian ) | D42: NC ROUTER NO.1 (HEIAN ER-4311-D4-2113/9100836) | E42: =B42 -> MNT00052 | H42: - | I42: CNC/SEMIAUTOMATIC | J42: FACTORY 1 | K42: WOOD WORKING | L42: S | M42: 41182 | N42: 10 | O42: Japan | P42: IoT
A43: MNT00053 | B43: MNT00053 | C43: NC Router ( Heian ) | D43: NC ROUTER NO.2 (HEIAN ER-431P-D4/9900418) | E43: =B43 -> MNT00053 | H43: - | I43: CNC/SEMIAUTOMATIC | J43: FACTORY 1 | K43: WOOD WORKING | L43: S | M43: 36707 | N43: 22 | O43: Japan | P43: IoT
A44: MNT00054 | B44: MNT00054 | C44: NC Router ( Heian ) | D44: NC ROUTER NO.3 (HEIAN ER-4311-D4-2113/9100836) | E44: =B44 -> MNT00054 | H44: - | I44: CNC/SEMIAUTOMATIC | J44: FACTORY 1 | K44: WOOD WORKING | L44: S | M44: 36433 | N44: 23 | O44: Japan | P44: IoT
A45: MNT00055 | B45: MNT00055 | C45: NC Router ( Heian ) | D45: NC ROUTER NO.4 (HEIAN ENC431P-1510 S/N:8901246) | E45: =B45 -> MNT00055 | H45: - | I45: CNC/SEMIAUTOMATIC | J45: FACTORY 1 | K45: WOOD WORKING | L45: S | M45: 40663 | N45: 11 | O45: Japan | P45: IoT
A46: MNT00056 | B46: MNT00056 | C46: NC Router ( Heian ) | D46: NC ROUTER NO.5 (HEIAN ENC431P-1510 S/N:8901247) | E46: =B46 -> MNT00056 | H46: - | I46: CNC/SEMIAUTOMATIC | J46: FACTORY 1 | K46: WOOD WORKING | L46: S | M46: 40663 | N46: 11 | O46: Japan | P46: IoT
A47: MNT00057 | B47: MNT00057 | C47: NC Router ( Heian ) | D47: NC ROUTER NO.6 (HEIAN ER-431-1310/2000680) | E47: =B47 -> MNT00057 | H47: - | I47: CNC/SEMIAUTOMATIC | J47: FACTORY 1 | K47: WOOD WORKING | L47: S | M47: 42613 | N47: 6 | O47: Japan | P47: IoT
A48: MNT00058 | B48: MNT00058 | C48: NC Router ( Heian ) | D48: NC ROUTER NO.7 (HEIAN ER-431P-1310/2000679) | E48: =B48 -> MNT00058 | H48: - | I48: CNC/SEMIAUTOMATIC | J48: FACTORY 1 | K48: WOOD WORKING | L48: S | M48: 42613 | N48: 6 | O48: Japan | P48: IoT
...

Sheet PIVOT2
A3: Row Labels
A4: Assy ( Manual/Orang )
A5: Band Saw
A6: Bench Saw
A7: Cold press Qiulin
A8: Cross cut
A9: DET
A10: Edge Bander
A11: Flat laminator
A12: Glue Spreader
A13: Hot Press
A14: Hozo Line
... A43: Grand Total

Sheet Data
A2: QR Code | B2: index | C2: category umum | D2: Category PE | E2: Category akhir | F2: Kode mesin
A3: MNT00001 | B3: 1 | C3: Band Saw | D3: Band Saw | E3: BAND SAW (SOCOMECC) | F3: =A3 -> MNT00001
A4: MNT00046 | B4: 2 | C4: Bench Saw | D4: Bench Saw Body Line | E4: BENCH SAW NO. 8 BODY LINE (TOKAI) | F4: =A4 -> MNT00046
A5: MNT00047 | B5: 2 | C5: Bench Saw | D5: Bench Saw Body Line | E5: BENCH SAW NO. 11 BODY LINE (TOKAI) | F5: =A5 -> MNT00047
A6: MNT00048 | B6: 2 | C6: Bench Saw | D6: Bench Saw Body Line | E6: BENCH SAW NO. 3 BODY LINE (AUTOFEEDER) | F6: =A6 -> MNT00048
A7: MNT00045 | B7: 2 | C7: Bench Saw | D7: Bench Saw cabinet assy | E7: BENCH SAW NO. 5 CABINET (TOKAI) | F7: =A7 -> MNT00045
A8: MNT00040 | B8: 2 | C8: Bench Saw | D8: Bench Saw cornerwood | E8: BENCH SAW NO. 1 CORNER WOOD (TOKAI) | F8: =A8 -> MNT00040
A9: MNT00041 | B9: 2 | C9: Bench Saw | D9: Bench Saw cornerwood | E9: BENCH SAW NO. 2 CORNER WOOD (TOKAI) | F9: =A9 -> MNT00041
A10: MNT00059 | B10: 2 | C10: Bench Saw | D10: Bench Saw cornerwood | E10: TRIANGLE SAW (TOKAI) | F10: =A10 -> MNT00059
A11: MNT00060 | B11: 2 | C11: Bench Saw | D11: Bench Saw cornerwood | E11: TABLE SAW NO. 1 CORNER WOOD (TOKAI) | F11: =A11 -> MNT00060
A12: MNT00042 | B12: 2 | C12: Bench Saw | D12: Bench Saw Line BR | E12: BENCH SAW NO. 11 LINE BR (HOLYTEK) | F12: =A12 -> MNT00042
A13: MNT00043 | B13: 2 | C13: Bench Saw | D13: Bench Saw Line BR | E13: BENCH SAW NO. 12 LINE BR (HOLYTEK) | F13: =A13 -> MNT00043
A14: MNT00044 | B14: 2 | C14: Bench Saw | D14: Bench Saw Line BR | E14: BENCH SAW NO. 13 LINE BR (HOLYTEK) | F14: =A14 -> MNT00044
... A99: MNT00000 | B99: 39 | C99: Assy ( Manual/Orang ) | D99: Assembly by hand/Man | E99: Assembly by Hand/Man | F99: =A99 -> MNT00000

Sheet Sheet4
A1: WW | B1: SMT-PCB
A2: Assy ( Manual/Orang ) | B2: YSP Printing
A3: Band Saw | B3: SPI KY
A4: Bench Saw | B4: YGD 1 Dispense
A5: Cold press Qiulin | B5: YGD 2 Dispense
A6: Cross cut | B6: YS24 Mounter
A7: DET | B7: YS100 Mounter
A8: Edge Bander | B8: YS88 Mounter
A9: Flat laminator | B9: YG12 Mounter
A10: Glue Spreader | B10: YG12F Mounter
A11: Hot Press | B11: YG100RB Mounter
A12: Hozo Line | B12: Oven Reflow
... A16: NC Router ( Heian ) | B16: Autoinsert RD Radial
A17: NCB 3 (WEEKE BHX 050)
A18: NCB1 Yasaka
A19: NCBR (Morbidelli)
A20: NCBR (Pratix)
A21: NCBR (SCM Z30)
A22: Onime Press
A23: Panel Saw
A24: Pin Router
A25: Press R top NS-600A
A26: Press R top NS-800A
A27: Press xxx side
A28: Profile Sander
... A40: WBS - Wide Belt Sander
